[2024-05-14T17:50:44.354+0000] {local_task_job_runner.py:120} INFO - ::group::Pre task execution logs
[2024-05-14T17:50:44.391+0000] {taskinstance.py:2076} INFO - Dependencies all met for dep_context=non-requeueable deps ti=<TaskInstance: Webscrape.Ingest_Data manual__2024-05-14T17:50:42.087767+00:00 [queued]>
[2024-05-14T17:50:44.396+0000] {taskinstance.py:2076} INFO - Dependencies all met for dep_context=requeueable deps ti=<TaskInstance: Webscrape.Ingest_Data manual__2024-05-14T17:50:42.087767+00:00 [queued]>
[2024-05-14T17:50:44.396+0000] {taskinstance.py:2306} INFO - Starting attempt 1 of 6
[2024-05-14T17:50:44.405+0000] {taskinstance.py:2330} INFO - Executing <Task(PythonOperator): Ingest_Data> on 2024-05-14 17:50:42.087767+00:00
[2024-05-14T17:50:44.476+0000] {standard_task_runner.py:90} INFO - Running: ['***', 'tasks', 'run', 'Webscrape', 'Ingest_Data', 'manual__2024-05-14T17:50:42.087767+00:00', '--job-id', '81', '--raw', '--subdir', 'DAGS_FOLDER/webscrapping.py', '--cfg-path', '/tmp/tmpw2s7zwtp']
[2024-05-14T17:50:44.478+0000] {logging_mixin.py:188} WARNING - /home/***/.local/lib/python3.12/site-packages/***/task/task_runner/standard_task_runner.py:61 DeprecationWarning: This process (pid=328) is multi-threaded, use of fork() may lead to deadlocks in the child.
[2024-05-14T17:50:44.502+0000] {standard_task_runner.py:91} INFO - Job 81: Subtask Ingest_Data
[2024-05-14T17:50:44.503+0000] {standard_task_runner.py:63} INFO - Started process 329 to run task
[2024-05-14T17:50:44.898+0000] {task_command.py:426} INFO - Running <TaskInstance: Webscrape.Ingest_Data manual__2024-05-14T17:50:42.087767+00:00 [running]> on host 4ac0c9fa8b6a
[2024-05-14T17:50:45.135+0000] {taskinstance.py:2648} INFO - Exporting env vars: AIRFLOW_CTX_DAG_OWNER='svc' AIRFLOW_CTX_DAG_ID='Webscrape' AIRFLOW_CTX_TASK_ID='Ingest_Data' AIRFLOW_CTX_EXECUTION_DATE='2024-05-14T17:50:42.087767+00:00' AIRFLOW_CTX_TRY_NUMBER='1' AIRFLOW_CTX_DAG_RUN_ID='manual__2024-05-14T17:50:42.087767+00:00'
[2024-05-14T17:50:45.139+0000] {taskinstance.py:430} INFO - ::endgroup::
[2024-05-14T17:50:45.234+0000] {conn.py:362} INFO - <BrokerConnection node_id=bootstrap-0 host=localhost:29092 <connecting> [IPv6 ('::1', 29092, 0, 0)]>: connecting to localhost:29092 [('::1', 29092, 0, 0) IPv6]
[2024-05-14T17:50:45.236+0000] {conn.py:957} INFO - Probing node bootstrap-0 broker version
[2024-05-14T17:50:45.238+0000] {conn.py:402} ERROR - Connect attempt to <BrokerConnection node_id=bootstrap-0 host=localhost:29092 <connecting> [IPv6 ('::1', 29092, 0, 0)]> returned error 111. Disconnecting.
[2024-05-14T17:50:45.238+0000] {conn.py:673} ERROR - <BrokerConnection node_id=bootstrap-0 host=localhost:29092 <connecting> [IPv6 ('::1', 29092, 0, 0)]>: Closing connection. KafkaConnectionError: 111 ECONNREFUSED
[2024-05-14T17:50:45.285+0000] {conn.py:362} INFO - <BrokerConnection node_id=bootstrap-0 host=localhost:29092 <connecting> [IPv6 ('::1', 29092, 0, 0)]>: connecting to localhost:29092 [('::1', 29092, 0, 0) IPv6]
[2024-05-14T17:50:45.286+0000] {conn.py:402} ERROR - Connect attempt to <BrokerConnection node_id=bootstrap-0 host=localhost:29092 <connecting> [IPv6 ('::1', 29092, 0, 0)]> returned error 111. Disconnecting.
[2024-05-14T17:50:45.286+0000] {conn.py:673} ERROR - <BrokerConnection node_id=bootstrap-0 host=localhost:29092 <connecting> [IPv6 ('::1', 29092, 0, 0)]>: Closing connection. KafkaConnectionError: 111 ECONNREFUSED
[2024-05-14T17:50:45.335+0000] {conn.py:362} INFO - <BrokerConnection node_id=bootstrap-0 host=localhost:29092 <connecting> [IPv4 ('127.0.0.1', 29092)]>: connecting to localhost:29092 [('127.0.0.1', 29092) IPv4]
[2024-05-14T17:50:45.336+0000] {conn.py:402} ERROR - Connect attempt to <BrokerConnection node_id=bootstrap-0 host=localhost:29092 <connecting> [IPv4 ('127.0.0.1', 29092)]> returned error 111. Disconnecting.
[2024-05-14T17:50:45.336+0000] {conn.py:673} ERROR - <BrokerConnection node_id=bootstrap-0 host=localhost:29092 <connecting> [IPv4 ('127.0.0.1', 29092)]>: Closing connection. KafkaConnectionError: 111 ECONNREFUSED
[2024-05-14T17:50:45.338+0000] {taskinstance.py:441} INFO - ::group::Post task execution logs
[2024-05-14T17:50:45.339+0000] {taskinstance.py:2905} ERROR - Task failed with exception
Traceback (most recent call last):
  File "/home/airflow/.local/lib/python3.12/site-packages/airflow/models/taskinstance.py", line 465, in _execute_task
    result = _execute_callable(context=context, **execute_callable_kwargs)
             ^^^^^^^^^^^^^^^^^^^^^^^^^^^^^^^^^^^^^^^^^^^^^^^^^^^^^^^^^^^^^
  File "/home/airflow/.local/lib/python3.12/site-packages/airflow/models/taskinstance.py", line 432, in _execute_callable
    return execute_callable(context=context, **execute_callable_kwargs)
           ^^^^^^^^^^^^^^^^^^^^^^^^^^^^^^^^^^^^^^^^^^^^^^^^^^^^^^^^^^^^
  File "/home/airflow/.local/lib/python3.12/site-packages/airflow/models/baseoperator.py", line 400, in wrapper
    return func(self, *args, **kwargs)
           ^^^^^^^^^^^^^^^^^^^^^^^^^^^
  File "/home/airflow/.local/lib/python3.12/site-packages/airflow/operators/python.py", line 235, in execute
    return_value = self.execute_callable()
                   ^^^^^^^^^^^^^^^^^^^^^^^
  File "/home/airflow/.local/lib/python3.12/site-packages/airflow/operators/python.py", line 252, in execute_callable
    return self.python_callable(*self.op_args, **self.op_kwargs)
           ^^^^^^^^^^^^^^^^^^^^^^^^^^^^^^^^^^^^^^^^^^^^^^^^^^^^^
  File "/opt/airflow/dags/includes/main.py", line 204, in ingestion_start
    asyncio.run(main())
  File "/usr/local/lib/python3.12/asyncio/runners.py", line 194, in run
    return runner.run(main)
           ^^^^^^^^^^^^^^^^
  File "/usr/local/lib/python3.12/asyncio/runners.py", line 118, in run
    return self._loop.run_until_complete(task)
           ^^^^^^^^^^^^^^^^^^^^^^^^^^^^^^^^^^^
  File "/usr/local/lib/python3.12/asyncio/base_events.py", line 687, in run_until_complete
    return future.result()
           ^^^^^^^^^^^^^^^
  File "/opt/airflow/dags/includes/main.py", line 199, in main
    producer = KafkaProducer(bootstrap_servers=["localhost:29092"])
               ^^^^^^^^^^^^^^^^^^^^^^^^^^^^^^^^^^^^^^^^^^^^^^^^^^^^
  File "/home/airflow/.local/lib/python3.12/site-packages/kafka/producer/kafka.py", line 383, in __init__
    client = self.config['kafka_client'](
             ^^^^^^^^^^^^^^^^^^^^^^^^^^^^
  File "/home/airflow/.local/lib/python3.12/site-packages/kafka/client_async.py", line 234, in __init__
    self.config['api_version'] = self.check_version(timeout=check_timeout)
                                 ^^^^^^^^^^^^^^^^^^^^^^^^^^^^^^^^^^^^^^^^^
  File "/home/airflow/.local/lib/python3.12/site-packages/kafka/client_async.py", line 902, in check_version
    raise Errors.NoBrokersAvailable()
kafka.errors.NoBrokersAvailable: NoBrokersAvailable
[2024-05-14T17:50:45.392+0000] {taskinstance.py:1206} INFO - Marking task as UP_FOR_RETRY. dag_id=Webscrape, task_id=Ingest_Data, run_id=manual__2024-05-14T17:50:42.087767+00:00, execution_date=20240514T175042, start_date=20240514T175044, end_date=20240514T175045
[2024-05-14T17:50:45.410+0000] {standard_task_runner.py:110} ERROR - Failed to execute job 81 for task Ingest_Data (NoBrokersAvailable; 329)
[2024-05-14T17:50:45.447+0000] {local_task_job_runner.py:240} INFO - Task exited with return code 1
[2024-05-14T17:50:45.463+0000] {taskinstance.py:3498} INFO - 0 downstream tasks scheduled from follow-on schedule check
[2024-05-14T17:50:45.464+0000] {local_task_job_runner.py:222} INFO - ::endgroup::
